Workbook

Sheet Samples

Sheet MS
A1: Date | B1: ID | C1: Pmax | D1: Isc | E1: Voc | F1: Ipm | G1: Vpm | H1: FF | I1: Rs | J1: Rsh | K1: Eff | L1: T_Object | M1: T_Target | N1: Class | O1: Sweep_Time | P1: Irr_MonCell | Q1: Isc_MonCell | R1: T_MonCell | S1: T_Ambient
B2: GS04875KG3022527291 | C2: 637.85217 | D2: 15.55787 | E2: 49.157885 | F2: 14.951709 | G2: 42.660821 | H2: 83.402046 | K2: 23.613765
B3: GS04875KG3022527570 | C3: 632.74664 | D3: 15.610009 | E3: 49.076441 | F3: 14.875613 | G3: 42.535836 | H3: 82.594976 | K3: 23.424754
B4: GS04875KG3022531004 | C4: 631.7838 | D4: 15.586583 | E4: 48.981368 | F4: 14.890207 | G4: 42.429484 | H4: 82.753556 | K4: 23.389109
B5: GS04875KG3022531491 | C5: 633.57749 | D5: 15.537084 | E5: 49.058244 | F5: 14.903184 | G5: 42.512895 | H5: 83.122428 | K5: 23.455512
B6: GS04875KG3022533046 | C6: 634.45861 | D6: 15.566301 | E6: 48.976978 | F6: 14.952973 | G6: 42.430267 | H6: 83.21965 | K6: 23.488132
B7: GS04875KG3022533102 | C7: 634.09682 | D7: 15.573389 | E7: 49.17061 | F7: 14.885933 | G7: 42.59705 | H7: 82.80696 | K7: 23.474739
B8: GS04875KG3022534288 | C8: 633.73309 | D8: 15.567755 | E8: 48.953224 | F8: 14.947519 | G8: 42.397209 | H8: 83.157054 | K8: 23.461273
B9: GS04875KG3022539048 | C9: 634.73082 | D9: 15.613946 | E9: 48.971484 | F9: 14.933485 | G9: 42.503864 | H9: 83.010618 | K9: 23.49821
B10: GS04875KG3022539168 | C10: 634.85653 | D10: 15.608492 | E10: 49.114813 | F10: 14.909099 | G10: 42.581819 | H10: 82.813692 | K10: 23.502864
B11: GS04875KG3022540510 | C11: 631.43806 | D11: 16.716471 | E11: 49.193921 | F11: 15.018726 | G11: 42.07744 | H11: 82.284706 | K11: 23.386309
B12: GS04875KG3022541679 | C12: 627.99172 | D12: 15.496879 | E12: 48.999282 | F12: 14.931502 | G12: 42.058174 | H12: 82.70275 | K12: 23.248723
B13: GS04875KG3022541791 | C13: 633.8765 | D13: 15.535176 | E13: 49.145088 | F13: 14.88776 | G13: 42.577024 | H13: 83.0249 | K13: 23.466582
... B64: GS04875KG3022581035 | C64: 637.5351 | D64: 15.543819 | E64: 49.216656 | F64: 14.951005 | G64: 42.641622 | H64: 83.336311 | K64: 23.602026
A65: 46029.554 | B65: GS04875KG3022531572 | C65: 627.31351 | D65: 15.653639 | E65: 49.108858 | F65: 14.945572 | G65: 41.973201 | H65: 81.60363 | I65: 0.376231 | J65: 554.66755 | K65: 23.223615 | L65: 21.4 | M65: 25 | N65: 2 | O65: 30 | P65: 992.23038 | Q65: 0.1383978 | R65: 22.408568 | S65: 22.4375
A66: 46029.563 | B66: GS04875KG3022542847 | C66: 626.61763 | D66: 15.62076 | E66: 49.159261 | F66: 14.901529 | G66: 42.050558 | H66: 81.600929 | I66: 0.372582 | J66: 376.79619 | K66: 23.197853 | L66: 21.46 | M66: 25 | N66: 2 | O66: 30 | P66: 992.30394 | Q66: 0.138408 | R66: 22.315375 | S66: 22.4375
A67: 46029.717 | B67: GS04875KG3022540326 | C67: 632.10565 | D67: 15.593859 | E67: 49.368655 | F67: 14.946992 | G67: 42.289822 | H67: 82.107868 | I67: 0.385224 | J67: 347.14511 | K67: 23.401024 | L67: 23.02 | M67: 25 | N67: 2 | O67: 30 | P67: 991.90445 | Q67: 0.1383528 | R67: 22.812371 | S67: 22.9375
A68: 46029.717 | B68: GS04875KG3022530908 | C68: 633.82404 | D68: 15.572481 | E68: 49.13206 | F68: 14.900054 | G68: 42.538371 | H68: 82.841115 | I68: 0.374205 | J68: 481.60719 | K68: 23.46464 | L68: 23.04 | M68: 25 | N68: 2 | O68: 30 | P68: 991.93183 | Q68: 0.1383566 | R68: 22.812371 | S68: 22.9375
A69: 46029.719 | B69: GS04875KG3022502254 | C69: 633.39291 | D69: 15.592299 | E69: 49.146451 | F69: 14.878658 | G69: 42.570568 | H69: 82.655337 | I69: 0.372905 | J69: 292.51259 | K69: 23.448679 | L69: 23.05 | M69: 25 | N69: 2 | O69: 30 | P69: 991.97016 | Q69: 0.138362 | R69: 22.812371 | S69: 22.9375
A70: 46029.719 | B70: GS04875KG3022537950 | C70: 633.41968 | D70: 15.621279 | E70: 49.142889 | F70: 15.05407 | G70: 42.076307 | H70: 82.511461 | I70: 0.372266 | J70: 192.48481 | K70: 23.44967 | L70: 23.07 | M70: 25 | N70: 3 | O70: 30 | P70: 991.88359 | Q70: 0.1383499 | R70: 22.843431 | S70: 22.9375
A71: 46029.72 | B71: GS04875KG3022536273 | C71: 633.54017 | D71: 15.550671 | E71: 49.139179 | F71: 14.891915 | G71: 42.542558 | H71: 82.908128 | I71: 0.371415 | J71: 575.6769 | K71: 23.454131 | L71: 23.04 | M71: 25 | N71: 2 | O71: 30 | P71: 991.90914 | Q71: 0.1383535 | R71: 22.843431 | S71: 23
A72: 46029.722 | B72: GS04875KG3022543092 | C72: 637.20377 | D72: 15.585503 | E72: 49.285431 | F72: 14.933112 | G72: 42.670529 | H72: 82.954313 | I72: 0.370606 | J72: 534.35259 | K72: 23.58976 | L72: 22.97 | M72: 25 | N72: 2 | O72: 30 | P72: 991.90445 | Q72: 0.1383528 | R72: 22.812371 | S72: 23
A73: 46029.722 | B73: GS04875KG3022542847 | C73: 634.25383 | D73: 15.571737 | E73: 49.288794 | F73: 14.854082 | G73: 42.69896 | H73: 82.637629 | I73: 0.368151 | J73: 366.40641 | K73: 23.480551 | L73: 23.04 | M73: 25 | N73: 1 | O73: 30 | P73: 991.92088 | Q73: 0.1383551 | R73: 22.812371 | S73: 23
A74: 46029.723 | B74: GS04875KG3022532867 | C74: 632.99952 | D74: 15.621674 | E74: 49.148636 | F74: 15.026922 | G74: 42.124364 | H74: 82.445004 | I74: 0.375885 | J74: 234.78028 | K74: 23.434116 | L74: 23.05 | M74: 25 | N74: 3 | O74: 30 | P74: 991.92636 | Q74: 0.1383559 | R74: 22.812371 | S74: 23
A75: 46029.727 | B75: GS04875KG3022532946 | C75: 634.07594 | D75: 15.670211 | E75: 49.175786 | F75: 15.039124 | G75: 42.161759 | H75: 82.283945 | I75: 0.375354 | J75: 261.86411 | K75: 23.380444 | L75: 23.09 | M75: 25 | N75: 3 | O75: 30 | P75: 995.92916 | Q75: 0.1389142 | R75: 22.812371 | S75: 23
A77: 46029 | B77: GS04875KG3022525996 | C77: 632.19764 | D77: 16.640719 | E77: 49.145668 | F77: 15.986503 | G77: 39.545712 | H77: 77.302855 | I77: 0.379657 | J77: 533.38513 | K77: 23.404429 | L77: 23.73 | M77: 25 | N77: 3 | O77: 30 | P77: 1006.9584 | Q77: 0.1384165 | R77: 22.874491 | S77: 22.5625
... A84: 46029.003 | B84: GS04875KG3022540629 | C84: 633.58618 | D84: 16.69504 | E84: 49.065471 | F84: 15.835334 | G84: 40.010914 | H84: 77.346781 | I84: 0.369236 | J84: 194.92372 | K84: 23.455834 | L84: 24.58 | M84: 25 | N84: 3 | O84: 30 | P84: 1006.8808 | Q84: 0.1384058 | R84: 22.936609 | S84: 22.6875

Sheet FTR(Inspection)
A1: Gautam Solar Private Limited.
A2: Flasher Test (Power Determination Test)
A3: Total Qty:- 48096Pcs Sample Qty:- 80Nos
A4: Date :-06/01/2026, 07/01/2026 & 08/01/2026
A5: Sr.No. | B5: Module Sr.No. | C5: Pmax | D5: Isc | E5: Voc | F5: Ipm | G5: Vpm | H5: FF | I5: Eff.
A6: Ref | B6: GS04800KG2552500001 REF | C6: 608.06 | D6: 15.34 | E6: 48.91 | F6: 14.36 | G6: 42.33 | H6: 81.03 | I6: 22.51 | K6: =IFERROR(VLOOKUP(B6,Samples!$A:$A,1,0),"Not Found") -> Not Found | L6: =COUNTIF($B$6:$B$1048576,B6) -> 1
A7: 1 | B7: GS04875KG3022540510 | C7: =VLOOKUP(B7,MS!$B:$K,2,0) -> 631.43806 | D7: =VLOOKUP(B7,MS!$B:$K,3,0) -> 16.716471 | E7: =VLOOKUP(B7,MS!$B:$K,4,0) -> 49.193921 | F7: =VLOOKUP(B7,MS!$B:$K,5,0) -> 15.018726 | G7: =VLOOKUP(B7,MS!$B:$K,6,0) -> 42.07744 | H7: =VLOOKUP(B7,MS!$B:$K,7,0) -> 82.284706 | I7: =VLOOKUP(B7,MS!$B:$K,10,0) -> 23.386309 | K7: =IFERROR(VLOOKUP(B7,Samples!$A:$A,1,0),"Not Found") -> Not Found | L7: =COUNTIF($B$6:$B$1048576,B7) -> 1
A8: 2 | B8: GS04875KG3022525996 | C8: =VLOOKUP(B8,MS!$B:$K,2,0) -> 632.19764 | D8: =VLOOKUP(B8,MS!$B:$K,3,0) -> 16.640719 | E8: =VLOOKUP(B8,MS!$B:$K,4,0) -> 49.145668 | F8: =VLOOKUP(B8,MS!$B:$K,5,0) -> 15.986503 | G8: =VLOOKUP(B8,MS!$B:$K,6,0) -> 39.545712 | H8: =VLOOKUP(B8,MS!$B:$K,7,0) -> 77.302855 | I8: =VLOOKUP(B8,MS!$B:$K,10,0) -> 23.404429 | K8: =IFERROR(VLOOKUP(B8,Samples!$A:$A,1,0),"Not Found") -> Not Found | L8: =COUNTIF($B$6:$B$1048576,B8) -> 1
A9: 3 | B9: GS04875KG3022532867 | C9: =VLOOKUP(B9,MS!$B:$K,2,0) -> 632.99952 | D9: =VLOOKUP(B9,MS!$B:$K,3,0) -> 15.621674 | E9: =VLOOKUP(B9,MS!$B:$K,4,0) -> 49.148636 | F9: =VLOOKUP(B9,MS!$B:$K,5,0) -> 15.026922 | G9: =VLOOKUP(B9,MS!$B:$K,6,0) -> 42.124364 | H9: =VLOOKUP(B9,MS!$B:$K,7,0) -> 82.445004 | I9: =VLOOKUP(B9,MS!$B:$K,10,0) -> 23.434116 | K9: =IFERROR(VLOOKUP(B9,Samples!$A:$A,1,0),"Not Found") -> Not Found | L9: =COUNTIF($B$6:$B$1048576,B9) -> 1
A10: 4 | B10: GS04875KG3022532946 | C10: =VLOOKUP(B10,MS!$B:$K,2,0) -> 634.07594 | D10: =VLOOKUP(B10,MS!$B:$K,3,0) -> 15.670211 | E10: =VLOOKUP(B10,MS!$B:$K,4,0) -> 49.175786 | F10: =VLOOKUP(B10,MS!$B:$K,5,0) -> 15.039124 | G10: =VLOOKUP(B10,MS!$B:$K,6,0) -> 42.161759 | H10: =VLOOKUP(B10,MS!$B:$K,7,0) -> 82.283945 | I10: =VLOOKUP(B10,MS!$B:$K,10,0) -> 23.380444 | K10: =IFERROR(VLOOKUP(B10,Samples!$A:$A,1,0),"Not Found") -> Not Found | L10: =COUNTIF($B$6:$B$1048576,B10) -> 1
A11: 5 | B11: GS04875KG3022530908 | C11: =VLOOKUP(B11,MS!$B:$K,2,0) -> 633.82404 | D11: =VLOOKUP(B11,MS!$B:$K,3,0) -> 15.572481 | E11: =VLOOKUP(B11,MS!$B:$K,4,0) -> 49.13206 | F11: =VLOOKUP(B11,MS!$B:$K,5,0) -> 14.900054 | G11: =VLOOKUP(B11,MS!$B:$K,6,0) -> 42.538371 | H11: =VLOOKUP(B11,MS!$B:$K,7,0) -> 82.841115 | I11: =VLOOKUP(B11,MS!$B:$K,10,0) -> 23.46464 | K11: =IFERROR(VLOOKUP(B11,Samples!$A:$A,1,0),"Not Found") -> Not Found | L11: =COUNTIF($B$6:$B$1048576,B11) -> 1
A12: 6 | B12: GS04875KG3022502254 | C12: =VLOOKUP(B12,MS!$B:$K,2,0) -> 633.39291 | D12: =VLOOKUP(B12,MS!$B:$K,3,0) -> 15.592299 | E12: =VLOOKUP(B12,MS!$B:$K,4,0) -> 49.146451 | F12: =VLOOKUP(B12,MS!$B:$K,5,0) -> 14.878658 | G12: =VLOOKUP(B12,MS!$B:$K,6,0) -> 42.570568 | H12: =VLOOKUP(B12,MS!$B:$K,7,0) -> 82.655337 | I12: =VLOOKUP(B12,MS!$B:$K,10,0) -> 23.448679 | K12: =IFERROR(VLOOKUP(B12,Samples!$A:$A,1,0),"Not Found") -> Not Found | L12: =COUNTIF($B$6:$B$1048576,B12) -> 1
A13: 7 | B13: GS04875KG3022536273 | C13: =VLOOKUP(B13,MS!$B:$K,2,0) -> 633.54017 | D13: =VLOOKUP(B13,MS!$B:$K,3,0) -> 15.550671 | E13: =VLOOKUP(B13,MS!$B:$K,4,0) -> 49.139179 | F13: =VLOOKUP(B13,MS!$B:$K,5,0) -> 14.891915 | G13: =VLOOKUP(B13,MS!$B:$K,6,0) -> 42.542558 | H13: =VLOOKUP(B13,MS!$B:$K,7,0) -> 82.908128 | I13: =VLOOKUP(B13,MS!$B:$K,10,0) -> 23.454131 | K13: =IFERROR(VLOOKUP(B13,Samples!$A:$A,1,0),"Not Found") -> Not Found | L13: =COUNTIF($B$6:$B$1048576,B13) -> 1
A14: 8 | B14: GS04875KG3022537950 | C14: =VLOOKUP(B14,MS!$B:$K,2,0) -> 633.41968 | D14: =VLOOKUP(B14,MS!$B:$K,3,0) -> 15.621279 | E14: =VLOOKUP(B14,MS!$B:$K,4,0) -> 49.142889 | F14: =VLOOKUP(B14,MS!$B:$K,5,0) -> 15.05407 | G14: =VLOOKUP(B14,MS!$B:$K,6,0) -> 42.076307 | H14: =VLOOKUP(B14,MS!$B:$K,7,0) -> 82.511461 | I14: =VLOOKUP(B14,MS!$B:$K,10,0) -> 23.44967 | K14: =IFERROR(VLOOKUP(B14,Samples!$A:$A,1,0),"Not Found") -> Not Found | L14: =COUNTIF($B$6:$B$1048576,B14) -> 1
A15: 9 | B15: GS04875KG3022522517 | C15: =VLOOKUP(B15,MS!$B:$K,2,0) -> 632.67953 | D15: =VLOOKUP(B15,MS!$B:$K,3,0) -> 16.747434 | E15: =VLOOKUP(B15,MS!$B:$K,4,0) -> 49.080992 | F15: =VLOOKUP(B15,MS!$B:$K,5,0) -> 16.033464 | G15: =VLOOKUP(B15,MS!$B:$K,6,0) -> 39.459941 | H15: =VLOOKUP(B15,MS!$B:$K,7,0) -> 76.970122 | I15: =VLOOKUP(B15,MS!$B:$K,10,0) -> 23.422269 | K15: =IFERROR(VLOOKUP(B15,Samples!$A:$A,1,0),"Not Found") -> Not Found | L15: =COUNTIF($B$6:$B$1048576,B15) -> 1
A16: 10 | B16: GS04875KG3022522147 | C16: =VLOOKUP(B16,MS!$B:$K,2,0) -> 634.29745 | D16: =VLOOKUP(B16,MS!$B:$K,3,0) -> 16.698293 | E16: =VLOOKUP(B16,MS!$B:$K,4,0) -> 49.241428 | F16: =VLOOKUP(B16,MS!$B:$K,5,0) -> 16.01622 | G16: =VLOOKUP(B16,MS!$B:$K,6,0) -> 39.603443 | H16: =VLOOKUP(B16,MS!$B:$K,7,0) -> 77.141888 | I16: =VLOOKUP(B16,MS!$B:$K,10,0) -> 23.482166 | K16: =IFERROR(VLOOKUP(B16,Samples!$A:$A,1,0),"Not Found") -> Not Found | L16: =COUNTIF($B$6:$B$1048576,B16) -> 1
A17: 11 | B17: GS04875KG3022543092 | C17: =VLOOKUP(B17,MS!$B:$K,2,0) -> 637.20377 | D17: =VLOOKUP(B17,MS!$B:$K,3,0) -> 15.585503 | E17: =VLOOKUP(B17,MS!$B:$K,4,0) -> 49.285431 | F17: =VLOOKUP(B17,MS!$B:$K,5,0) -> 14.933112 | G17: =VLOOKUP(B17,MS!$B:$K,6,0) -> 42.670529 | H17: =VLOOKUP(B17,MS!$B:$K,7,0) -> 82.954313 | I17: =VLOOKUP(B17,MS!$B:$K,10,0) -> 23.58976 | K17: =IFERROR(VLOOKUP(B17,Samples!$A:$A,1,0),"Not Found") -> Not Found | L17: =COUNTIF($B$6:$B$1048576,B17) -> 1
A18: 12 | B18: GS04875KG3022542847 | C18: =VLOOKUP(B18,MS!$B:$K,2,0) -> 626.61763 | D18: =VLOOKUP(B18,MS!$B:$K,3,0) -> 15.62076 | E18: =VLOOKUP(B18,MS!$B:$K,4,0) -> 49.159261 | F18: =VLOOKUP(B18,MS!$B:$K,5,0) -> 14.901529 | G18: =VLOOKUP(B18,MS!$B:$K,6,0) -> 42.050558 | H18: =VLOOKUP(B18,MS!$B:$K,7,0) -> 81.600929 | I18: =VLOOKUP(B18,MS!$B:$K,10,0) -> 23.197853 | K18: =IFERROR(VLOOKUP(B18,Samples!$A:$A,1,0),"Not Found") -> Not Found | L18: =COUNTIF($B$6:$B$1048576,B18) -> 1
... A86: 80 | B86: GS04875KG3022540629 | C86: =VLOOKUP(B86,MS!$B:$K,2,0) -> 633.58618 | D86: =VLOOKUP(B86,MS!$B:$K,3,0) -> 16.69504 | E86: =VLOOKUP(B86,MS!$B:$K,4,0) -> 49.065471 | F86: =VLOOKUP(B86,MS!$B:$K,5,0) -> 15.835334 | G86: =VLOOKUP(B86,MS!$B:$K,6,0) -> 40.010914 | H86: =VLOOKUP(B86,MS!$B:$K,7,0) -> 77.346781 | I86: =VLOOKUP(B86,MS!$B:$K,10,0) -> 23.455834 | K86: =IFERROR(VLOOKUP(B86,Samples!$A:$A,1,0),"Not Found") -> Not Found | L86: =COUNTIF($B$6:$B$1048576,B86) -> 1
K87: =IFERROR(VLOOKUP(B87,Samples!$A:$A,1,0),"Not Found") -> Not Found | L87: =COUNTIF($B$6:$B$1048576,B87) -> 0

Sheet Bifaciality
A1: Gautam Solar Private Limited.
A2: Bi-Faciality of Solar PV Module
A3: Total Qty:- 48096Pcs Sample Qty:- 14 Nos
A4: Date :-06/01/2026, 07/01/2026 & 08/01/2026
A5: Sr. No. | B5: Module Serial No. | C5: Front Side Electrical Parameter | J5: Rare Side Electrical Parameter | Q5: Bi-faciality Factor(≥70%)
C6: Pmax | D6: Isc | E6: Voc | F6: Ipm | G6: Vpm | H6: FF | I6: eff | J6: Pmax | K6: Isc | L6: Voc | M6: Ipm | N6: Vpm | O6: FF | P6: eff
A7: 1 | B7: GS04875KG3022502254 | C7: =VLOOKUP(B7,'FTR(Inspection)'!$B$5:$I$57,2,0) -> 633.39291 | D7: =VLOOKUP(B7,'FTR(Inspection)'!$B$5:$I$57,3,0) -> 15.592299 | E7: =VLOOKUP(B7,'FTR(Inspection)'!$B$5:$I$57,4,0) -> 49.146451 | F7: =VLOOKUP(B7,'FTR(Inspection)'!$B$5:$I$57,5,0) -> 14.878658 | G7: =VLOOKUP(B7,'FTR(Inspection)'!$B$5:$I$57,6,0) -> 42.570568 | H7: =VLOOKUP(B7,'FTR(Inspection)'!$B$5:$I$57,7,0) -> 82.655337 | I7: =VLOOKUP(B7,'FTR(Inspection)'!$B$5:$I$57,8,0) -> 23.448679 | J7: 489.80048 | K7: 12.738305 | L7: 48.795617 | M7: 11.406227 | N7: 42.941497 | O7: 78.800098 | P7: 18.060538 | Q7: =J7*100/C7 -> 77.329643 | S7: =IFERROR(VLOOKUP(B7,Samples!$A:$A,1,0),"Not Found") -> Not Found | T7: =COUNTIF(B7:B14,B7) -> 1
A8: 2 | B8: GS04875KG3022522147 | C8: =VLOOKUP(B8,'FTR(Inspection)'!$B$5:$I$57,2,0) -> 634.29745 | D8: =VLOOKUP(B8,'FTR(Inspection)'!$B$5:$I$57,3,0) -> 16.698293 | E8: =VLOOKUP(B8,'FTR(Inspection)'!$B$5:$I$57,4,0) -> 49.241428 | F8: =VLOOKUP(B8,'FTR(Inspection)'!$B$5:$I$57,5,0) -> 16.01622 | G8: =VLOOKUP(B8,'FTR(Inspection)'!$B$5:$I$57,6,0) -> 39.603443 | H8: =VLOOKUP(B8,'FTR(Inspection)'!$B$5:$I$57,7,0) -> 77.141888 | I8: =VLOOKUP(B8,'FTR(Inspection)'!$B$5:$I$57,8,0) -> 23.482166 | J8: 497.86885 | K8: 12.610226 | L8: 49.049357 | M8: 11.531858 | N8: 43.173341 | O8: 80.493124 | P8: 18.358045 | Q8: =J8*100/C8 -> 78.491385 | S8: =IFERROR(VLOOKUP(B8,Samples!$A:$A,1,0),"Not Found") -> Not Found | T8: =COUNTIF(B8:B14,B8) -> 1
A9: 3 | B9: GS04875KG3022522517 | C9: =VLOOKUP(B9,'FTR(Inspection)'!$B$5:$I$57,2,0) -> 632.67953 | D9: =VLOOKUP(B9,'FTR(Inspection)'!$B$5:$I$57,3,0) -> 16.747434 | E9: =VLOOKUP(B9,'FTR(Inspection)'!$B$5:$I$57,4,0) -> 49.080992 | F9: =VLOOKUP(B9,'FTR(Inspection)'!$B$5:$I$57,5,0) -> 16.033464 | G9: =VLOOKUP(B9,'FTR(Inspection)'!$B$5:$I$57,6,0) -> 39.459941 | H9: =VLOOKUP(B9,'FTR(Inspection)'!$B$5:$I$57,7,0) -> 76.970122 | I9: =VLOOKUP(B9,'FTR(Inspection)'!$B$5:$I$57,8,0) -> 23.422269 | J9: 497.98199 | K9: 12.709383 | L9: 49.009791 | M9: 11.545112 | N9: 43.133578 | O9: 79.947763 | P9: 18.362217 | Q9: =J9*100/C9 -> 78.709989 | S9: =IFERROR(VLOOKUP(B9,Samples!$A:$A,1,0),"Not Found") -> Not Found | T9: =COUNTIF(B9:B15,B9) -> 1
A10: 4 | B10: GS04875KG3022525996 | C10: =VLOOKUP(B10,'FTR(Inspection)'!$B$5:$I$57,2,0) -> 632.19764 | D10: =VLOOKUP(B10,'FTR(Inspection)'!$B$5:$I$57,3,0) -> 16.640719 | E10: =VLOOKUP(B10,'FTR(Inspection)'!$B$5:$I$57,4,0) -> 49.145668 | F10: =VLOOKUP(B10,'FTR(Inspection)'!$B$5:$I$57,5,0) -> 15.986503 | G10: =VLOOKUP(B10,'FTR(Inspection)'!$B$5:$I$57,6,0) -> 39.545712 | H10: =VLOOKUP(B10,'FTR(Inspection)'!$B$5:$I$57,7,0) -> 77.302855 | I10: =VLOOKUP(B10,'FTR(Inspection)'!$B$5:$I$57,8,0) -> 23.404429 | J10: 502.17142 | K10: 12.84774 | L10: 48.934667 | M10: 11.657698 | N10: 43.076379 | O10: 79.874587 | P10: 18.516695 | Q10: =J10*100/C10 -> 79.432663 | S10: =IFERROR(VLOOKUP(B10,Samples!$A:$A,1,0),"Not Found") -> Not Found | T10: =COUNTIF(B10:B16,B10) -> 1
A11: 5 | B11: GS04875KG3022530908 | C11: =VLOOKUP(B11,'FTR(Inspection)'!$B$5:$I$57,2,0) -> 633.82404 | D11: =VLOOKUP(B11,'FTR(Inspection)'!$B$5:$I$57,3,0) -> 15.572481 | E11: =VLOOKUP(B11,'FTR(Inspection)'!$B$5:$I$57,4,0) -> 49.13206 | F11: =VLOOKUP(B11,'FTR(Inspection)'!$B$5:$I$57,5,0) -> 14.900054 | G11: =VLOOKUP(B11,'FTR(Inspection)'!$B$5:$I$57,6,0) -> 42.538371 | H11: =VLOOKUP(B11,'FTR(Inspection)'!$B$5:$I$57,7,0) -> 82.841115 | I11: =VLOOKUP(B11,'FTR(Inspection)'!$B$5:$I$57,8,0) -> 23.46464 | J11: 480.58114 | K11: 12.738747 | L11: 48.740507 | M11: 11.211081 | N11: 42.86662 | O11: 77.401605 | P11: 17.720591 | Q11: =J11*100/C11 -> 75.822486 | S11: =IFERROR(VLOOKUP(B11,Samples!$A:$A,1,0),"Not Found") -> Not Found | T11: =COUNTIF(B11:B18,B11) -> 1
A12: 6 | B12: GS04875KG3022531572 | C12: =VLOOKUP(B12,'FTR(Inspection)'!$B$5:$I$57,2,0) -> 627.31351 | D12: =VLOOKUP(B12,'FTR(Inspection)'!$B$5:$I$57,3,0) -> 15.653639 | E12: =VLOOKUP(B12,'FTR(Inspection)'!$B$5:$I$57,4,0) -> 49.108858 | F12: =VLOOKUP(B12,'FTR(Inspection)'!$B$5:$I$57,5,0) -> 14.945572 | G12: =VLOOKUP(B12,'FTR(Inspection)'!$B$5:$I$57,6,0) -> 41.973201 | H12: =VLOOKUP(B12,'FTR(Inspection)'!$B$5:$I$57,7,0) -> 81.60363 | I12: =VLOOKUP(B12,'FTR(Inspection)'!$B$5:$I$57,8,0) -> 23.223615 | J12: 507.22328 | K12: 12.922891 | L12: 48.909993 | M12: 11.78054 | N12: 43.056029 | O12: 80.249418 | P12: 18.702973 | Q12: =J12*100/C12 -> 80.856425 | S12: =IFERROR(VLOOKUP(B12,Samples!$A:$A,1,0),"Not Found") -> Not Found | T12: =COUNTIF(B12:B20,B12) -> 1
A13: 7 | B13: GS04875KG3022532867 | C13: =VLOOKUP(B13,'FTR(Inspection)'!$B$5:$I$57,2,0) -> 632.99952 | D13: =VLOOKUP(B13,'FTR(Inspection)'!$B$5:$I$57,3,0) -> 15.621674 | E13: =VLOOKUP(B13,'FTR(Inspection)'!$B$5:$I$57,4,0) -> 49.148636 | F13: =VLOOKUP(B13,'FTR(Inspection)'!$B$5:$I$57,5,0) -> 15.026922 | G13: =VLOOKUP(B13,'FTR(Inspection)'!$B$5:$I$57,6,0) -> 42.124364 | H13: =VLOOKUP(B13,'FTR(Inspection)'!$B$5:$I$57,7,0) -> 82.445004 | I13: =VLOOKUP(B13,'FTR(Inspection)'!$B$5:$I$57,8,0) -> 23.434116 | J13: 492.5332 | K13: 12.724383 | L13: 48.743302 | M13: 11.489016 | N13: 42.869922 | O13: 79.411577 | P13: 18.161302 | Q13: =J13*100/C13 -> 77.809411 | S13: =IFERROR(VLOOKUP(B13,Samples!$A:$A,1,0),"Not Found") -> Not Found | T13: =COUNTIF(B13:B21,B13) -> 1
A14: 8 | B14: GS04875KG3022532946 | C14: =VLOOKUP(B14,'FTR(Inspection)'!$B$5:$I$57,2,0) -> 634.07594 | D14: =VLOOKUP(B14,'FTR(Inspection)'!$B$5:$I$57,3,0) -> 15.670211 | E14: =VLOOKUP(B14,'FTR(Inspection)'!$B$5:$I$57,4,0) -> 49.175786 | F14: =VLOOKUP(B14,'FTR(Inspection)'!$B$5:$I$57,5,0) -> 15.039124 | G14: =VLOOKUP(B14,'FTR(Inspection)'!$B$5:$I$57,6,0) -> 42.161759 | H14: =VLOOKUP(B14,'FTR(Inspection)'!$B$5:$I$57,7,0) -> 82.283945 | I14: =VLOOKUP(B14,'FTR(Inspection)'!$B$5:$I$57,8,0) -> 23.380444 | J14: 490.1513 | K14: 12.706868 | L14: 48.726961 | M14: 11.427644 | N14: 42.89172 | O14: 79.163011 | P14: 18.073474 | Q14: =J14*100/C14 -> 77.301672 | S14: =IFERROR(VLOOKUP(B14,Samples!$A:$A,1,0),"Not Found") -> Not Found | T14: =COUNTIF(B14:B22,B14) -> 1
A15: 9 | B15: GS04875KG3022536273 | C15: =VLOOKUP(B15,'FTR(Inspection)'!$B$5:$I$57,2,0) -> 633.54017 | D15: =VLOOKUP(B15,'FTR(Inspection)'!$B$5:$I$57,3,0) -> 15.550671 | E15: =VLOOKUP(B15,'FTR(Inspection)'!$B$5:$I$57,4,0) -> 49.139179 | F15: =VLOOKUP(B15,'FTR(Inspection)'!$B$5:$I$57,5,0) -> 14.891915 | G15: =VLOOKUP(B15,'FTR(Inspection)'!$B$5:$I$57,6,0) -> 42.542558 | H15: =VLOOKUP(B15,'FTR(Inspection)'!$B$5:$I$57,7,0) -> 82.908128 | I15: =VLOOKUP(B15,'FTR(Inspection)'!$B$5:$I$57,8,0) -> 23.454131 | J15: 483.98818 | K15: 12.737206 | L15: 48.738884 | M15: 11.288519 | N15: 42.874374 | O15: 77.962361 | P15: 17.846219 | Q15: =J15*100/C15 -> 76.394237
A16: 10 | B16: GS04875KG3022537950 | C16: =VLOOKUP(B16,'FTR(Inspection)'!$B$5:$I$57,2,0) -> 633.41968 | D16: =VLOOKUP(B16,'FTR(Inspection)'!$B$5:$I$57,3,0) -> 15.621279 | E16: =VLOOKUP(B16,'FTR(Inspection)'!$B$5:$I$57,4,0) -> 49.142889 | F16: =VLOOKUP(B16,'FTR(Inspection)'!$B$5:$I$57,5,0) -> 15.05407 | G16: =VLOOKUP(B16,'FTR(Inspection)'!$B$5:$I$57,6,0) -> 42.076307 | H16: =VLOOKUP(B16,'FTR(Inspection)'!$B$5:$I$57,7,0) -> 82.511461 | I16: =VLOOKUP(B16,'FTR(Inspection)'!$B$5:$I$57,8,0) -> 23.44967 | J16: 495.11669 | K16: 12.802438 | L16: 48.790657 | M16: 11.542579 | N16: 42.894806 | O16: 79.26441 | P16: 18.256564 | Q16: =J16*100/C16 -> 78.165663
A17: 11 | B17: GS04875KG3022540326 | C17: =VLOOKUP(B17,'FTR(Inspection)'!$B$5:$I$57,2,0) -> 632.10565 | D17: =VLOOKUP(B17,'FTR(Inspection)'!$B$5:$I$57,3,0) -> 15.593859 | E17: =VLOOKUP(B17,'FTR(Inspection)'!$B$5:$I$57,4,0) -> 49.368655 | F17: =VLOOKUP(B17,'FTR(Inspection)'!$B$5:$I$57,5,0) -> 14.946992 | G17: =VLOOKUP(B17,'FTR(Inspection)'!$B$5:$I$57,6,0) -> 42.289822 | H17: =VLOOKUP(B17,'FTR(Inspection)'!$B$5:$I$57,7,0) -> 82.107868 | I17: =VLOOKUP(B17,'FTR(Inspection)'!$B$5:$I$57,8,0) -> 23.401024 | J17: 506.95697 | K17: 12.895223 | L17: 48.959686 | M17: 11.761108 | N17: 43.104526 | O17: 80.297795 | P17: 18.693154 | Q17: =J17*100/C17 -> 80.201303
A18: 12 | B18: GS04875KG3022540559 | C18: =VLOOKUP(B18,'FTR(Inspection)'!$B$5:$I$57,2,0) -> 630.99165 | D18: =VLOOKUP(B18,'FTR(Inspection)'!$B$5:$I$57,3,0) -> 16.681355 | E18: =VLOOKUP(B18,'FTR(Inspection)'!$B$5:$I$57,4,0) -> 49.103301 | F18: =VLOOKUP(B18,'FTR(Inspection)'!$B$5:$I$57,5,0) -> 15.99964 | G18: =VLOOKUP(B18,'FTR(Inspection)'!$B$5:$I$57,6,0) -> 39.437867 | H18: =VLOOKUP(B18,'FTR(Inspection)'!$B$5:$I$57,7,0) -> 77.033852 | I18: =VLOOKUP(B18,'FTR(Inspection)'!$B$5:$I$57,8,0) -> 23.359783 | J18: 500.95268 | K18: 12.984662 | L18: 48.801287 | M18: 11.66232 | N18: 42.954803 | O18: 79.055992 | P18: 18.471756 | Q18: =J18*100/C18 -> 79.391333
A19: 13 | B19: GS04875KG3022542847 | C19: =VLOOKUP(B19,'FTR(Inspection)'!$B$5:$I$57,2,0) -> 626.61763 | D19: =VLOOKUP(B19,'FTR(Inspection)'!$B$5:$I$57,3,0) -> 15.62076 | E19: =VLOOKUP(B19,'FTR(Inspection)'!$B$5:$I$57,4,0) -> 49.159261 | F19: =VLOOKUP(B19,'FTR(Inspection)'!$B$5:$I$57,5,0) -> 14.901529 | G19: =VLOOKUP(B19,'FTR(Inspection)'!$B$5:$I$57,6,0) -> 42.050558 | H19: =VLOOKUP(B19,'FTR(Inspection)'!$B$5:$I$57,7,0) -> 81.600929 | I19: =VLOOKUP(B19,'FTR(Inspection)'!$B$5:$I$57,8,0) -> 23.197853 | J19: 485.05107 | K19: 12.683717 | L19: 48.891911 | M19: 11.278251 | N19: 43.007651 | O19: 78.217495 | P19: 17.885412 | Q19: =J19*100/C19 -> 77.407824
A20: 14 | B20: GS04875KG3022543092 | C20: =VLOOKUP(B20,'FTR(Inspection)'!$B$5:$I$57,2,0) -> 637.20377 | D20: =VLOOKUP(B20,'FTR(Inspection)'!$B$5:$I$57,3,0) -> 15.585503 | E20: =VLOOKUP(B20,'FTR(Inspection)'!$B$5:$I$57,4,0) -> 49.285431 | F20: =VLOOKUP(B20,'FTR(Inspection)'!$B$5:$I$57,5,0) -> 14.933112 | G20: =VLOOKUP(B20,'FTR(Inspection)'!$B$5:$I$57,6,0) -> 42.670529 | H20: =VLOOKUP(B20,'FTR(Inspection)'!$B$5:$I$57,7,0) -> 82.954313 | I20: =VLOOKUP(B20,'FTR(Inspection)'!$B$5:$I$57,8,0) -> 23.58976 | J20: 488.20615 | K20: 12.6676 | L20: 48.89228 | M20: 11.352872 | N20: 43.002877 | O20: 78.82584 | P20: 18.00175 | Q20: =J20*100/C20 -> 76.616958

Sheet Visual Inspection Sheet
A1: Gautam Solar Private Limited.
A2: Visual Inspection Checksheet
A3: Total Qty:- 48096Pcs Sample Qty:- 80 Nos
A4: Date :-06/01/2026, 07/01/2026 & 08/01/2026
A5: SL.NO | B5: MODULE ID | C5: Defects | D5: Remark | F5: =IFERROR(VLOOKUP(B6,Samples!$A:$A,1,0),"Not Found") -> Not Found | G5: =COUNTIF(B5:B56,B5) -> 1
A6: 1 | B6: GS04875KG3022540510 | C6: Nil | D6: OK | F6: =IFERROR(VLOOKUP(B7,Samples!$A:$A,1,0),"Not Found") -> Not Found | G6: =COUNTIF(B6:B56,B6) -> 1
A7: 2 | B7: GS04875KG3022525996 | C7: Nil | D7: OK | F7: =IFERROR(VLOOKUP(B8,Samples!$A:$A,1,0),"Not Found") -> Not Found | G7: =COUNTIF(B7:B56,B7) -> 1
A8: 3 | B8: GS04875KG3022532867 | C8: Nil | D8: OK | F8: =IFERROR(VLOOKUP(B9,Samples!$A:$A,1,0),"Not Found") -> Not Found | G8: =COUNTIF(B8:B56,B8) -> 1
A9: 4 | B9: GS04875KG3022532946 | C9: Nil | D9: OK | F9: =IFERROR(VLOOKUP(B10,Samples!$A:$A,1,0),"Not Found") -> Not Found | G9: =COUNTIF(B9:B56,B9) -> 1
A10: 5 | B10: GS04875KG3022530908 | C10: Nil | D10: OK | F10: =IFERROR(VLOOKUP(B11,Samples!$A:$A,1,0),"Not Found") -> Not Found | G10: =COUNTIF(B10:B56,B10) -> 1
A11: 6 | B11: GS04875KG3022502254 | C11: Nil | D11: OK | F11: =IFERROR(VLOOKUP(B12,Samples!$A:$A,1,0),"Not Found") -> Not Found | G11: =COUNTIF(B11:B56,B11) -> 1
A12: 7 | B12: GS04875KG3022536273 | C12: Nil | D12: OK | F12: =IFERROR(VLOOKUP(B13,Samples!$A:$A,1,0),"Not Found") -> Not Found | G12: =COUNTIF(B12:B56,B12) -> 1
A13: 8 | B13: GS04875KG3022537950 | C13: Nil | D13: OK | F13: =IFERROR(VLOOKUP(B14,Samples!$A:$A,1,0),"Not Found") -> Not Found | G13: =COUNTIF(B13:B56,B13) -> 1
A14: 9 | B14: GS04875KG3022522517 | C14: Nil | D14: OK | F14: =IFERROR(VLOOKUP(B15,Samples!$A:$A,1,0),"Not Found") -> Not Found | G14: =COUNTIF(B14:B56,B14) -> 1
A15: 10 | B15: GS04875KG3022522147 | C15: Nil | D15: OK | F15: =IFERROR(VLOOKUP(B16,Samples!$A:$A,1,0),"Not Found") -> Not Found | G15: =COUNTIF(B15:B56,B15) -> 1
A16: 11 | B16: GS04875KG3022543092 | C16: Nil | D16: OK | F16: =IFERROR(VLOOKUP(B17,Samples!$A:$A,1,0),"Not Found") -> Not Found | G16: =COUNTIF(B16:B56,B16) -> 1
A17: 12 | B17: GS04875KG3022542847 | C17: Nil | D17: OK | F17: =IFERROR(VLOOKUP(B18,Samples!$A:$A,1,0),"Not Found") -> Not Found | G17: =COUNTIF(B17:B56,B17) -> 1
A18: 13 | B18: GS04875KG3022540326 | C18: Nil | D18: OK | F18: =IFERROR(VLOOKUP(B19,Samples!$A:$A,1,0),"Not Found") -> Not Found | G18: =COUNTIF(B18:B56,B18) -> 1
A19: 14 | B19: GS04875KG3022531572 | C19: Nil | D19: OK | F19: =IFERROR(VLOOKUP(B20,Samples!$A:$A,1,0),"Not Found") -> Not Found | G19: =COUNTIF(B19:B56,B19) -> 1
A20: 15 | B20: GS04875KG3022527291 | C20: Nil | D20: OK | F20: =IFERROR(VLOOKUP(B21,Samples!$A:$A,1,0),"Not Found") -> Not Found | G20: =COUNTIF(B20:B56,B20) -> 1
A21: 16 | B21: GS04875KG3022527570 | C21: Nil | D21: OK | F21: =IFERROR(VLOOKUP(B22,Samples!$A:$A,1,0),"Not Found") -> Not Found | G21: =COUNTIF(B21:B56,B21) -> 1
A22: 17 | B22: GS04875KG3022531004 | C22: Nil | D22: OK | F22: =IFERROR(VLOOKUP(B23,Samples!$A:$A,1,0),"Not Found") -> Not Found | G22: =COUNTIF(B22:B56,B22) -> 1
A23: 18 | B23: GS04875KG3022531491 | C23: Nil | D23: OK | F23: =IFERROR(VLOOKUP(B24,Samples!$A:$A,1,0),"Not Found") -> Not Found | G23: =COUNTIF(B23:B56,B23) -> 1
A24: 19 | B24: GS04875KG3022533046 | C24: Nil | D24: OK | F24: =IFERROR(VLOOKUP(B25,Samples!$A:$A,1,0),"Not Found") -> Not Found | G24: =COUNTIF(B24:B56,B24) -> 1
A25: 20 | B25: GS04875KG3022533102 | C25: Nil | D25: OK | F25: =IFERROR(VLOOKUP(B26,Samples!$A:$A,1,0),"Not Found") -> Not Found | G25: =COUNTIF(B25:B56,B25) -> 1
A26: 21 | B26: GS04875KG3022534288 | C26: Nil | D26: OK | F26: =IFERROR(VLOOKUP(B27,Samples!$A:$A,1,0),"Not Found") -> Not Found | G26: =COUNTIF(B26:B56,B26) -> 1
A27: 22 | B27: GS04875KG3022539048 | C27: Nil | D27: OK | F27: =IFERROR(VLOOKUP(B28,Samples!$A:$A,1,0),"Not Found") -> Not Found | G27: =COUNTIF(B27:B56,B27) -> 1
A28: 23 | B28: GS04875KG3022539168 | C28: Nil | D28: OK | F28: =IFERROR(VLOOKUP(B29,Samples!$A:$A,1,0),"Not Found") -> Not Found | G28: =COUNTIF(B28:B56,B28) -> 1
A29: 24 | B29: GS04875KG3022540559 | C29: Nil | D29: OK | F29: =IFERROR(VLOOKUP(B30,Samples!$A:$A,1,0),"Not Found") -> Not Found | G29: =COUNTIF(B29:B56,B29) -> 1
A30: 25 | B30: GS04875KG3022541679 | C30: Nil | D30: OK | F30: =IFERROR(VLOOKUP(B31,Samples!$A:$A,1,0),"Not Found") -> Not Found | G30: =COUNTIF(B30:B56,B30) -> 1
A31: 26 | B31: GS04875KG3022541791 | C31: Nil | D31: OK | F31: =IFERROR(VLOOKUP(B32,Samples!$A:$A,1,0),"Not Found") -> Not Found | G31: =COUNTIF(B31:B56,B31) -> 1
A32: 27 | B32: GS04875KG3022542219 | C32: Nil | D32: OK | F32: =IFERROR(VLOOKUP(B33,Samples!$A:$A,1,0),"Not Found") -> Not Found | G32: =COUNTIF(B32:B56,B32) -> 1
A33: 28 | B33: GS04875KG3022542263 | C33: Nil | D33: OK | F33: =IFERROR(VLOOKUP(B34,Samples!$A:$A,1,0),"Not Found") -> Not Found | G33: =COUNTIF(B33:B56,B33) -> 1
A34: 29 | B34: GS04875KG3022546229 | C34: Nil | D34: OK | F34: =IFERROR(VLOOKUP(B35,Samples!$A:$A,1,0),"Not Found") -> Not Found | G34: =COUNTIF(B34:B56,B34) -> 1
A35: 30 | B35: GS04875KG3022546301 | C35: Nil | D35: OK | F35: =IFERROR(VLOOKUP(B36,Samples!$A:$A,1,0),"Not Found") -> Not Found | G35: =COUNTIF(B35:B56,B35) -> 1
A36: 31 | B36: GS04875KG3022546333 | C36: Nil | D36: OK | F36: =IFERROR(VLOOKUP(B37,Samples!$A:$A,1,0),"Not Found") -> Not Found | G36: =COUNTIF(B36:B56,B36) -> 1
A37: 32 | B37: GS04875KG3022546420 | C37: Nil | D37: OK | F37: =IFERROR(VLOOKUP(B38,Samples!$A:$A,1,0),"Not Found") -> Not Found | G37: =COUNTIF(B37:B56,B37) -> 1
A38: 33 | B38: GS04875KG3022546741 | C38: Nil | D38: OK | F38: =IFERROR(VLOOKUP(B39,Samples!$A:$A,1,0),"Not Found") -> Not Found | G38: =COUNTIF(B38:B56,B38) -> 1
A39: 34 | B39: GS04875KG3022547068 | C39: Nil | D39: OK | F39: =IFERROR(VLOOKUP(B40,Samples!$A:$A,1,0),"Not Found") -> Not Found | G39: =COUNTIF(B39:B56,B39) -> 1
A40: 35 | B40: GS04875KG3022550070 | C40: Nil | D40: OK | F40: =IFERROR(VLOOKUP(B41,Samples!$A:$A,1,0),"Not Found") -> Not Found | G40: =COUNTIF(B40:B56,B40) -> 1
...

Sheet EL Inspection Sheet
A1: Gautam Solar Private Limited.
A2: EL Inspection Checksheet
A3: Total Qty:- 48096Pcs Sample Qty:- 14 Nos
A4: Date :-06/01/2026, 07/01/2026 & 08/01/2026
A5: SL.NO | B5: MODULE ID | C5: Defects | D5: Remark
A6: 1 | B6: GS04875KG3022502254 | C6: Nil | D6: Ok
A7: 2 | B7: GS04875KG3022522147 | C7: Nil | D7: Ok
A8: 3 | B8: GS04875KG3022522517 | C8: Nil | D8: Ok
A9: 4 | B9: GS04875KG3022525996 | C9: Nil | D9: Ok
A10: 5 | B10: GS04875KG3022530908 | C10: Nil | D10: Ok
A11: 6 | B11: GS04875KG3022531572 | C11: Nil | D11: Ok
A12: 7 | B12: GS04875KG3022532867 | C12: Nil | D12: Ok
A13: 8 | B13: GS04875KG3022532946 | C13: Nil | D13: Ok
A14: 9 | B14: GS04875KG3022536273 | C14: Nil | D14: Ok
A15: 10 | B15: GS04875KG3022537950 | C15: Nil | D15: Ok
A16: 11 | B16: GS04875KG3022540326 | C16: Nil | D16: Ok
A17: 12 | B17: GS04875KG3022540559 | C17: Nil | D17: Ok
... A19: 14 | B19: GS04875KG3022543092 | C19: Nil | D19: Ok

Sheet IR,HV,GD,Wet Leakage
A1: Gautam Solar Private Limited.
A2: IR, HV, Ground continuity & Wet Leakage Test
A3: Total Qty:- 48096Pcs Sample Qty:-14 Nos
A4: Date :-06/01/2026, 07/01/2026 & 08/01/2026
A5: SL.NO | B5: MODULE ID | C5: IR TEST(≥40MΩ.m²) at 1500V for 1 min. | D5: DCW TEST (<50µA) at 4.8kv for 1 min. | E5: GROUND CONTINUITY TEST (<0.1Ω) at 62.5A | F5: Wet Leakage Test(IR≥40MΩ.m²) at 1500V for 2 min. | G5: REMARKS
A6: 1 | B6: GS04875KG3022502254 | C6: 3.11 | D6: 1.1 | E6: 4.03 | F6: 2.04
A7: 2 | B7: GS04875KG3022522147 | C7: 4.78 | D7: 1.2 | E7: 4.99 | F7: 3.37
A8: 3 | B8: GS04875KG3022522517 | C8: 4.21 | D8: 1.1 | E8: 4.81 | F8: 2.86
A9: 4 | B9: GS04875KG3022525996 | C9: 4.09 | D9: 1.1 | E9: 4.72 | F9: 3.8
A10: 5 | B10: GS04875KG3022530908 | C10: 4.5 | D10: 1.1 | E10: 3.89 | F10: 3.07
A11: 6 | B11: GS04875KG3022531572 | C11: 3.27 | D11: 1.2 | E11: 3.85 | F11: 3.5
A12: 7 | B12: GS04875KG3022532867 | C12: 3.26 | D12: 1 | E12: 3.71 | F12: 3.55
A13: 8 | B13: GS04875KG3022532946 | C13: 4.05 | D13: 1.1 | E13: 4.51 | F13: 2.95
A14: 9 | B14: GS04875KG3022536273 | C14: 4.2 | D14: 1.6 | E14: 4.82 | F14: 2.61
A15: 10 | B15: GS04875KG3022537950 | C15: 4.23 | D15: 1.1 | E15: 3.21 | F15: 2.9
A16: 11 | B16: GS04875KG3022540326 | C16: 5.21 | D16: 1.2 | E16: 3.51 | F16: 2.34
A17: 12 | B17: GS04875KG3022540559 | C17: 5.27 | D17: 1.3 | E17: 3.66 | F17: 4.3
... A19: 14 | B19: GS04875KG3022543092 | C19: 5.11 | D19: 1.2 | E19: 3.52 | F19: 2.94

Sheet Dimension
A1: Gautam Solar Private Limited.
A2: Dimension & Anodizing Coating Thickness Measurement Report
A3: Total Qty:- 48096Pcs Sample Qty:-14 Nos
A4: Date :-06/01/2026, 07/01/2026 & 08/01/2026
A5: Sr. No. | B5: Module ID | C5: Module length | D5: Module width | E5: Module Thickness(Profile) | F5: Diagonal 1 | G5: Diagonal 2 | H5: Diagonal difference | I5: Mounting hole to mounting hole distance 1# | J5: Mounting hole to mounting hole distance 2# | K5: Mounting hole to mounting hole distance 3# | L5: Mountain hole1 (Length * width) | M5: Cable Length | N5: Connector type | O5: Ground hole nos as per Drawing | P5: Drain Hole as per Drawing | Q5: Anodizing Coating Thickness
C6: mm | D6: mm | E6: mm | F6: mm | G6: mm | H6: mm | I6: (mm) | J6: (mm) | K6: (mm) | L6: mm*mm | M6: mm | Q6: µm
A7: 1 | B7: GS04875KG3022502254 | C7: 2382 | D7: 1134 | E7: 30 | F7: 2636 | G7: 2636 | H7: =G7-F7 -> 0 | I7: 1400 | J7: 790 | K7: 400 | L7: 14*9 | M7: 1200 | N7: MC4 | O7: 2 | P7: OK | Q7: 16.9
A8: 2 | B8: GS04875KG3022522147 | C8: 2382 | D8: 1134 | E8: 30 | F8: 2636 | G8: 2636 | H8: =G8-F8 -> 0 | I8: 1400 | J8: 790 | K8: 400 | L8: 14*9 | M8: 1200 | N8: MC4 | O8: 2 | P8: OK | Q8: 17.3
A9: 3 | B9: GS04875KG3022522517 | C9: 2382 | D9: 1134 | E9: 30 | F9: 2636 | G9: 2636 | H9: =G9-F9 -> 0 | I9: 1400 | J9: 790 | K9: 400 | L9: 14*9 | M9: 1200 | N9: MC4 | O9: 2 | P9: OK | Q9: 17.6
A10: 4 | B10: GS04875KG3022525996 | C10: 2382 | D10: 1134 | E10: 30 | F10: 2636 | G10: 2636 | H10: =G10-F10 -> 0 | I10: 1400 | J10: 790 | K10: 400 | L10: 14*9 | M10: 1200 | N10: MC4 | O10: 2 | P10: OK | Q10: 18.1
A11: 5 | B11: GS04875KG3022530908 | C11: 2382 | D11: 1134 | E11: 30 | F11: 2636 | G11: 2636 | H11: =G11-F11 -> 0 | I11: 1400 | J11: 790 | K11: 400 | L11: 14*9 | M11: 1200 | N11: MC4 | O11: 2 | P11: OK | Q11: 17.2
A12: 6 | B12: GS04875KG3022531572 | C12: 2382 | D12: 1134 | E12: 30 | F12: 2636 | G12: 2636 | H12: =G12-F12 -> 0 | I12: 1400 | J12: 790 | K12: 400 | L12: 14*9 | M12: 1200 | N12: MC4 | O12: 2 | P12: OK | Q12: 17.1
A13: 7 | B13: GS04875KG3022532867 | C13: 2382 | D13: 1134 | E13: 30 | F13: 2636 | G13: 2636 | H13: =G13-F13 -> 0 | I13: 1400 | J13: 790 | K13: 400 | L13: 14*9 | M13: 1200 | N13: MC4 | O13: 2 | P13: OK | Q13: 19.6
A14: 8 | B14: GS04875KG3022532946 | C14: 2382 | D14: 1134 | E14: 30 | F14: 2636 | G14: 2636 | H14: =G14-F14 -> 0 | I14: 1400 | J14: 790 | K14: 400 | L14: 14*9 | M14: 1200 | N14: MC4 | O14: 2 | P14: OK | Q14: 16.4
A15: 9 | B15: GS04875KG3022536273 | C15: 2382 | D15: 1134 | E15: 30 | F15: 2636 | G15: 2636 | H15: =G15-F15 -> 0 | I15: 1400 | J15: 790 | K15: 400 | L15: 14*9 | M15: 1200 | N15: MC4 | O15: 2 | P15: OK | Q15: 19.3
A16: 10 | B16: GS04875KG3022537950 | C16: 2382 | D16: 1134 | E16: 30 | F16: 2636 | G16: 2636 | H16: =G16-F16 -> 0 | I16: 1400 | J16: 790 | K16: 400 | L16: 14*9 | M16: 1200 | N16: MC4 | O16: 2 | P16: OK | Q16: 16.5
A17: 11 | B17: GS04875KG3022540326 | C17: 2382 | D17: 1134 | E17: 30 | F17: 2636 | G17: 2636 | H17: =G17-F17 -> 0 | I17: 1400 | J17: 790 | K17: 400 | L17: 14*9 | M17: 1200 | N17: MC4 | O17: 2 | P17: OK | Q17: 17.8
A18: 12 | B18: GS04875KG3022540559 | C18: 2382 | D18: 1134 | E18: 30 | F18: 2636 | G18: 2636 | H18: =G18-F18 -> 0 | I18: 1400 | J18: 790 | K18: 400 | L18: 14*9 | M18: 1200 | N18: MC4 | O18: 2 | P18: OK | Q18: 16.8
... A20: 14 | B20: GS04875KG3022543092 | C20: 2382 | D20: 1134 | E20: 30 | F20: 2636 | G20: 2636 | H20: =G20-F20 -> 0 | I20: 1400 | J20: 790 | K20: 400 | L20: 14*9 | M20: 1200 | N20: MC4 | O20: 2 | P20: OK | Q20: 19.3

Sheet RFID
A1: Gautam Solar Private Limited.
A2: RFID Inspection Report
A3: Total Qty:- 48096Pcs Sample Qty:-14 Nos
A4: Date :-06/01/2026, 07/01/2026 & 08/01/2026
A5: id | B5: s_no | C5: m_type | D5: manufacture_pv_module | E5: manufacture_solar_cell | F5: month_year_solar_cells | G5: month_year_module_pv | H5: p_max_the_module | I5: v_max_the_module | J5: i_max_the_module | K5: ff | L5: v_o_c_ | M5: i_s_c | N5: lab_issuing_iec_certificate | O5: date_obtain_ice_certificate
A6: 1 | B6: GS04875KG3022502254 | C6: 625W | D6: GSPL | E6: SOLARSPACE | F6: Aug, 25 | G6: Nov, 25 | H6: 630.733 | I6: 40.602 | J6: 15.534 | K6: 79.963 | L6: 48.722 | M6: 16.189 | N6: DTH | O6: 45675
A7: 2 | B7: GS04875KG3022522147 | C7: 625W | D7: GSPL | E7: SOLARSPACE | F7: Aug, 25 | G7: Nov, 25 | H7: 625.501 | I7: 40.564 | J7: 15.42 | K7: 79.268 | L7: 48.683 | M7: 16.209 | N7: DTH | O7: 45675
A8: 3 | B8: GS04875KG3022522517 | C8: 625W | D8: GSPL | E8: SOLARSPACE | F8: Aug, 25 | G8: Nov, 25 | H8: 628.558 | I8: 40.627 | J8: 15.472 | K8: 79.653 | L8: 48.728 | M8: 16.195 | N8: DTH | O8: 45675
A9: 4 | B9: GS04875KG3022525996 | C9: 625W | D9: GSPL | E9: SOLARSPACE | F9: Aug, 25 | G9: Nov, 25 | H9: 628.503 | I9: 40.619 | J9: 15.473 | K9: 79.488 | L9: 48.736 | M9: 16.224 | N9: DTH | O9: 45675
A10: 5 | B10: GS04875KG3022530908 | C10: 625W | D10: GSPL | E10: SOLARSPACE | F10: Aug, 25 | G10: Nov, 25 | H10: 629.834 | I10: 40.613 | J10: 15.508 | K10: 79.596 | L10: 48.747 | M10: 16.233 | N10: DTH | O10: 45675
A11: 6 | B11: GS04875KG3022531572 | C11: 625W | D11: GSPL | E11: SOLARSPACE | F11: Aug, 25 | G11: Nov, 25 | H11: 625.949 | I11: 40.589 | J11: 15.422 | K11: 79.281 | L11: 48.726 | M11: 16.204 | N11: DTH | O11: 45675
A12: 7 | B12: GS04875KG3022532867 | C12: 625W | D12: GSPL | E12: SOLARSPACE | F12: Aug, 25 | G12: Nov, 25 | H12: 626.064 | I12: 40.628 | J12: 15.41 | K12: 79.394 | L12: 48.714 | M12: 16.188 | N12: DTH | O12: 45675
A13: 8 | B13: GS04875KG3022532946 | C13: 625W | D13: GSPL | E13: SOLARSPACE | F13: Aug, 25 | G13: Nov, 25 | H13: 625.218 | I13: 40.57 | J13: 15.411 | K13: 79.286 | L13: 48.736 | M13: 16.18 | N13: DTH | O13: 45675
A14: 9 | B14: GS04875KG3022536273 | C14: 625W | D14: GSPL | E14: SOLARSPACE | F14: Aug, 25 | G14: Nov, 25 | H14: 629.854 | I14: 40.556 | J14: 15.531 | K14: 79.777 | L14: 48.745 | M14: 16.197 | N14: DTH | O14: 45675
A15: 10 | B15: GS04875KG3022537950 | C15: 625W | D15: GSPL | E15: SOLARSPACE | F15: Aug, 25 | G15: Nov, 25 | H15: 630.722 | I15: 40.648 | J15: 15.516 | K15: 79.806 | L15: 48.697 | M15: 16.229 | N15: DTH | O15: 45675
A16: 11 | B16: GS04875KG3022540326 | C16: 625W | D16: GSPL | E16: SOLARSPACE | F16: Aug, 25 | G16: Nov, 25 | H16: 626.039 | I16: 40.583 | J16: 15.426 | K16: 79.34 | L16: 48.721 | M16: 16.195 | N16: DTH | O16: 45675
A17: 12 | B17: GS04875KG3022540559 | C17: 625W | D17: GSPL | E17: SOLARSPACE | F17: Aug, 25 | G17: Nov, 25 | H17: 626.821 | I17: 40.569 | J17: 15.451 | K17: 79.303 | L17: 48.694 | M17: 16.232 | N17: DTH | O17: 45675
... A19: 14 | B19: GS04875KG3022543092 | C19: 625W | D19: GSPL | E19: SOLARSPACE | F19: Aug, 25 | G19: Nov, 25 | H19: 628.891 | I19: 40.61 | J19: 15.486 | K19: 79.475 | L19: 48.725 | M19: 16.24 | N19: DTH | O19: 45675
